File: packages/radie/radie-0.1.4.tar.gz/radie-0.1.4/radie/plugins/examples/data/xrd.ras
*RAS_DATA_START
*RAS_HEADER_START
*CORR_POS_DB_NAME "Correct"
*CORR_POS_GONIO_RADIUS ""
*CORR_POS_NODE_INDEX01 ""
*CORR_POS_NODE_INDEX02 ""
*CORR_POS_NODE_INDEX03 ""
*CORR_POS_NODE_INDEX04 ""
*CORR_POS_NODE_INDEX05 ""
*CORR_POS_NODE_INDEX06 ""
*CORR_POS_NODE_INDEX07 ""
*CORR_POS_NODE_INDEX08 ""
*CORR_POS_NODE_INDEX09 ""
*CORR_POS_NODE_INDEX10 ""
*CORR_POS_NODE_INDEX11 ""
*CORR_POS_NODE_LABEL01 "Si(111)"
*CORR_POS_NODE_LABEL02 "Si(220)"
*CORR_POS_NODE_LABEL03 "Si(311)"
*CORR_POS_NODE_LABEL04 "Si(400)"
*CORR_POS_NODE_LABEL05 "Si(331)"
*CORR_POS_NODE_LABEL06 "Si(422)"
*CORR_POS_NODE_LABEL07 "Si(511)"
*CORR_POS_NODE_LABEL08 "Si(440)"
*CORR_POS_NODE_LABEL09 "Si(531)"
*CORR_POS_NODE_LABEL10 "Si(620)"
*CORR_POS_NODE_LABEL11 "Si(533)"
*CORR_POS_NODE_POS_CALC01 "28.377"
*CORR_POS_NODE_POS_CALC02 "47.2506"
*CORR_POS_NODE_POS_CALC03 "56.0725"
*CORR_POS_NODE_POS_CALC04 "69.0822"
*CORR_POS_NODE_POS_CALC05 "76.3294"
*CORR_POS_NODE_POS_CALC06 "87.9853"
*CORR_POS_NODE_POS_CALC07 "94.9091"
*CORR_POS_NODE_POS_CALC08 "106.668"
*CORR_POS_NODE_POS_CALC09 "114.054"
*CORR_POS_NODE_POS_CALC10 "127.511"
*CORR_POS_NODE_POS_CALC11 "136.864"
*CORR_POS_NODE_POS_MEAS01 "28.3748"
*CORR_POS_NODE_POS_MEAS02 "47.2433"
*CORR_POS_NODE_POS_MEAS03 "56.0578"
*CORR_POS_NODE_POS_MEAS04 "69.0704"
*CORR_POS_NODE_POS_MEAS05 "76.3153"
*CORR_POS_NODE_POS_MEAS06 "87.9774"
*CORR_POS_NODE_POS_MEAS07 "94.9047"
*CORR_POS_NODE_POS_MEAS08 "106.671"
*CORR_POS_NODE_POS_MEAS09 "114.058"
*CORR_POS_NODE_POS_MEAS10 "127.513"
*CORR_POS_NODE_POS_MEAS11 "136.874"
*CORR_POS_OPT_ATTR "�W���@"
*CORR_POS_PARAM_MU ""
*CORR_POS_PARAM_PL ""
*CORR_POS_SEMODEL_TYPE "0"
*CORR_POS_STANDARD_TYPE ""
*CORR_POS_VALUE_ANALYZER "None"
*CORR_POS_VALUE_CMONO "None"
*CORR_POS_VALUE_IMONO "None"
*CORR_POS_VALUE_IS "1.250deg"
*CORR_POS_VALUE_ISL "10.0mm"
*CORR_POS_VALUE_ISOLLER "5.0deg"
*CORR_POS_VALUE_RS1 "1.250deg"
*CORR_POS_VALUE_RS2 "0.3mm"
*CORR_POS_VALUE_RSOLLER "5.0deg"
*CORR_POS_XG_FOCUS_L ""
*CORR_POS_XG_WAVE_TYPE ""
*CORR_POS_XG_WAVE_VALUE ""
*DISP_FMT_X "%.2f"
*DISP_FMT_Y "%.0f"
*DISP_FULLSCALE "665.0000000000"
*DISP_LINE_COLOR "255.0000000000"
*DISP_LINE_STYLE "0.0000000000"
*DISP_LINE_WIDTH "0.2500000000"
*DISP_NOTE "Collected Data-56"
*DISP_OFFSET_Y "0.0000000000"
*DISP_PEAKSEARCH_UNIT_Y "cps"
*DISP_RANGE_BOTTOM "0.0000000000"
*DISP_RANGE_LEFT "15.0000000000"
*DISP_RANGE_LOGCUTOFF "0.0100000000"
*DISP_RANGE_RIGHT "50.0000000000"
*DISP_RANGE_TOP "665.0000000000"
*DISP_SCALE_MODE_Y "0.0000000000"
*DISP_TAB_NAME "Theta/2-Theta"
*DISP_TITLE_Y "Intensity"
*DISP_UNIT_Y "cps"
*DISP_WINDOW_NAME "MSG_MACROENGINE"
*FILE_COMMENT " "
*FILE_MD5 ""
*FILE_MEMO " "
*FILE_OPERATOR "Administrator"
*FILE_SAMPLE "Ferrite XRD"
*FILE_TYPE "RAS_RAW"
*FILE_USERGROUP "System Manager"
*FILE_VERSION "1.0000000000"
*HW_ATTACHMENT_ID "ATT1025"
*HW_ATTACHMENT_NAME "�W��������|Standard Sample Holder"
*HW_COUNTER_ID-0 "CUT0021"
*HW_COUNTER_ID-1 "CUT0020"
*HW_COUNTER_ID-2 "CUT0020"
*HW_COUNTER_ID-3 "CMC0021"
*HW_COUNTER_NAME-0 "SC-70|SC-70"
*HW_COUNTER_NAME-1 "None|None"
*HW_COUNTER_NAME-2 "None|None"
*HW_COUNTER_NAME-3 "���o�탂�m�N�����[�^|Detector monochromator"
*HW_COUNTER_SELECT_NAME "SC-70|SC-70"
*HW_ECP_HV "655.5000000000"
*HW_ECP_HV_UNIT "V"
*HW_GONIOMETER_ID "GON0070"
*HW_GONIOMETER_NAME "MiniFlex 300/600|MiniFlex 300/600"
*HW_GONIOMETER_RADIUS-0 "79.0"
*HW_GONIOMETER_RADIUS-1 "91.5"
*HW_GONIOMETER_RADIUS-2 "150.0"
*HW_GONIOMETER_RADIUS-3 "0"
*HW_GONIOMETER_RADIUS-4 "103.4"
*HW_GONIOMETER_RADIUS-5 "150.0"
*HW_GONIOMETER_RADIUS-6 "46.6"
*HW_GONIOMETER_RADIUS-7 "160.0"
*HW_I_OPT_ID-0 "ISL0021"
*HW_I_OPT_ID-1 "ISO0021"
*HW_I_OPT_NAME-0 "���U�X���b�g|Divergence slit"
*HW_I_OPT_NAME-1 "���˕��s�X���b�g|Incident parallel slit"
*HW_R_ATTENUATER_AUTOMODE "0"
*HW_R_OPT_ID-0 "RSS0021"
*HW_R_OPT_ID-1 "RSO0021"
*HW_R_OPT_ID-2 "RRS0021"
*HW_R_OPT_NAME-0 "�U���X���b�g|Scattering slit"
*HW_R_OPT_NAME-1 "������s�X���b�g|Receiving soller slit"
*HW_R_OPT_NAME-2 "����X���b�g|Receiving slit"
*HW_SAMPLE_HOLDER_ID "SMP0000"
*HW_SAMPLE_HOLDER_NAME "����|None"
*HW_XG_CURRENT_MAX "15"
*HW_XG_CURRENT_MIN "2"
*HW_XG_CURRENT_RESOLUTION "1"
*HW_XG_CURRENT_UNIT "mA"
*HW_XG_FOCUS "1mm x 10mm"
*HW_XG_FOCUS_TYPE "Normal"
*HW_XG_ID ""
*HW_XG_NAME "300W/600W ������-B|300W/600W Sealed tube-B"
*HW_XG_TARGET_ATOMIC_NUMBER "29.0000000000"
*HW_XG_TARGET_NAME "Cu"
*HW_XG_TYPE "Hermetic"
*HW_XG_VOLTAGE_MAX "40"
*HW_XG_VOLTAGE_MIN "20"
*HW_XG_VOLTAGE_RESOLUTION "1"
*HW_XG_VOLTAGE_UNIT "kV"
*HW_XG_WATT_MAX "1"
*HW_XG_WATT_UNIT "kW"
*HW_XG_WAVE_LENGTH_ALPHA1 "1.540593"
*HW_XG_WAVE_LENGTH_ALPHA2 "1.544414"
*HW_XG_WAVE_LENGTH_BETA "1.392250"
*MEAS_COND_AXIS_NAME-0 "Theta/2-Theta"
*MEAS_COND_AXIS_NAME-1 "Soller(inc.)"
*MEAS_COND_AXIS_NAME-2 "IHS"
*MEAS_COND_AXIS_NAME-3 "DS"
*MEAS_COND_AXIS_NAME-4 "SS"
*MEAS_COND_AXIS_NAME-5 "Soller(rec.)"
*MEAS_COND_AXIS_NAME-6 "RS"
*MEAS_COND_AXIS_NAME-7 "Filter"
*MEAS_COND_AXIS_NAME-8 "Monochromator"
*MEAS_COND_AXIS_NAME-9 "HV"
*MEAS_COND_AXIS_NAME-10 "PHA"
*MEAS_COND_AXIS_NAME_INTERNAL-0 "TwoThetaTheta"
*MEAS_COND_AXIS_NAME_INTERNAL-1 "IncidentSollerSlit"
*MEAS_COND_AXIS_NAME_INTERNAL-2 "IncidentAxdSlit"
*MEAS_COND_AXIS_NAME_INTERNAL-3 "IncidentSlitBox"
*MEAS_COND_AXIS_NAME_INTERNAL-4 "ReceivingSlitBox1"
*MEAS_COND_AXIS_NAME_INTERNAL-5 "ReceivingSollerSlit"
*MEAS_COND_AXIS_NAME_INTERNAL-6 "ReceivingSlitBox2"
*MEAS_COND_AXIS_NAME_INTERNAL-7 "Filter"
*MEAS_COND_AXIS_NAME_INTERNAL-8 "CounterMonochromator"
*MEAS_COND_AXIS_NAME_INTERNAL-9 "HV"
*MEAS_COND_AXIS_NAME_INTERNAL-10 "PHA"
*MEAS_COND_AXIS_NAME_MAGICNO-0 "268632064.0000000000"
*MEAS_COND_AXIS_NAME_MAGICNO-1 "20971521.0000000000"
*MEAS_COND_AXIS_NAME_MAGICNO-2 "22020097.0000000000"
*MEAS_COND_AXIS_NAME_MAGICNO-3 "22020097.0000000000"
*MEAS_COND_AXIS_NAME_MAGICNO-4 "23068673.0000000000"
*MEAS_COND_AXIS_NAME_MAGICNO-5 "20971521.0000000000"
*MEAS_COND_AXIS_NAME_MAGICNO-6 "23068673.0000000000"
*MEAS_COND_AXIS_NAME_MAGICNO-7 "20971521.0000000000"
*MEAS_COND_AXIS_NAME_MAGICNO-8 "20971521.0000000000"
*MEAS_COND_AXIS_NAME_MAGICNO-9 "0.0000000000"
*MEAS_COND_AXIS_NAME_MAGICNO-10 "0.0000000000"
*MEAS_COND_AXIS_OFFSET-0 "0.0000000000"
*MEAS_COND_AXIS_OFFSET-1 "-"
*MEAS_COND_AXIS_OFFSET-2 "-"
*MEAS_COND_AXIS_OFFSET-3 "-"
*MEAS_COND_AXIS_OFFSET-4 "-"
*MEAS_COND_AXIS_OFFSET-5 "-"
*MEAS_COND_AXIS_OFFSET-6 "-"
*MEAS_COND_AXIS_OFFSET-7 "-"
*MEAS_COND_AXIS_OFFSET-8 "-"
*MEAS_COND_AXIS_OFFSET-9 "-"
*MEAS_COND_AXIS_OFFSET-10 "-"
*MEAS_COND_AXIS_POSITION-0 "10.0000000000"
*MEAS_COND_AXIS_POSITION-1 "5.0deg"
*MEAS_COND_AXIS_POSITION-2 "10.0mm"
*MEAS_COND_AXIS_POSITION-3 "1.250deg"
*MEAS_COND_AXIS_POSITION-4 "1.250deg"
*MEAS_COND_AXIS_POSITION-5 "5.0deg"
*MEAS_COND_AXIS_POSITION-6 "0.3mm"
*MEAS_COND_AXIS_POSITION-7 "None"
*MEAS_COND_AXIS_POSITION-8 "Bent"
*MEAS_COND_AXIS_POSITION-9 "655.5000000000"
*MEAS_COND_AXIS_POSITION-10 "555.0000000000"
*MEAS_COND_AXIS_UNIT-0 "deg"
*MEAS_COND_AXIS_UNIT-1 ""
*MEAS_COND_AXIS_UNIT-2 ""
*MEAS_COND_AXIS_UNIT-3 ""
*MEAS_COND_AXIS_UNIT-4 ""
*MEAS_COND_AXIS_UNIT-5 ""
*MEAS_COND_AXIS_UNIT-6 ""
*MEAS_COND_AXIS_UNIT-7 ""
*MEAS_COND_AXIS_UNIT-8 ""
*MEAS_COND_AXIS_UNIT-9 "V"
*MEAS_COND_AXIS_UNIT-10 "mV"
*MEAS_COND_CORRECTION_SLIT_COUNTERMONO "None"
*MEAS_COND_CORRECTION_SLIT_DS "1.250deg"
*MEAS_COND_CORRECTION_SLIT_FILTER "None"
*MEAS_COND_CORRECTION_SLIT_IHS "10.0mm"
*MEAS_COND_CORRECTION_SLIT_RS "0.3mm"
*MEAS_COND_CORRECTION_SLIT_SOLLER_INC "5.0deg"
*MEAS_COND_CORRECTION_SLIT_SOLLER_REC "5.0deg"
*MEAS_COND_CORRECTION_SLIT_SS "1.250deg"
*MEAS_COND_COUNTER_CNTLOSS_CORR "0.0000000000"
*MEAS_COND_COUNTER_PHABASE "555.0000000000"
*MEAS_COND_COUNTER_PHAWINDOW "925.0000000000"
*MEAS_COND_COUNTER_PHA_UNIT "mV"
*MEAS_COND_COUNTER_TAUDIFF "0.2500000000"
*MEAS_COND_COUNTER_TAUINT "0.7500000000"
*MEAS_COND_IRRADIATION_MODE "OFF"
*MEAS_COND_IRRADIATION_WIDTH ""
*MEAS_COND_OPT_ATTR " "
*MEAS_COND_OPT_NAME ""
*MEAS_COND_UNSYMMETRIC_MODE "OFF"
*MEAS_COND_XG_CURRENT "15.0000000000"
*MEAS_COND_XG_VOLTAGE "40.0000000000"
*MEAS_COND_XG_WAVE_TYPE "Ka"
*MEAS_DATA_COUNT "1751.0000000000"
*MEAS_SCAN_AXIS_X "Theta/2-Theta"
*MEAS_SCAN_AXIS_X_INTERNAL "TwoThetaTheta"
*MEAS_SCAN_END_TIME "09/22/15 13:12:58"
*MEAS_SCAN_MODE "CONTINUOUS"
*MEAS_SCAN_MONITOR "0"
*MEAS_SCAN_RESOLUTION_X "0.0025"
*MEAS_SCAN_SPEED "2.5000"
*MEAS_SCAN_SPEED_UNIT "deg/min"
*MEAS_SCAN_START "15.0000000000"
*MEAS_SCAN_START_TIME "09/22/15 12:58:51"
*MEAS_SCAN_STEP "0.0200000000"
*MEAS_SCAN_STOP "50.0000000000"
*MEAS_SCAN_UNIT_X "deg"
*MEAS_SCAN_UNIT_Y "counts"
*SLIT_SYSTEM "0"
*RAS_HEADER_END
*RAS_INT_START
15.0000 22.0000 1.0000
15.0400 24.0000 1.0000
15.0800 26.0000 1.0000
15.1200 26.0000 1.0000
15.1600 30.0000 1.0000
15.2000 21.0000 1.0000
15.2400 20.0000 1.0000
15.2800 25.0000 1.0000
15.3200 31.0000 1.0000
15.3600 23.0000 1.0000
15.4000 32.0000 1.0000
15.4400 23.0000 1.0000
15.4800 25.0000 1.0000
15.5200 16.0000 1.0000
15.5600 20.0000 1.0000
15.6000 25.0000 1.0000
15.6400 18.0000 1.0000
15.6800 29.0000 1.0000
15.7200 27.0000 1.0000
15.7600 33.0000 1.0000
15.8000 28.0000 1.0000
15.8400 14.0000 1.0000
15.8800 24.0000 1.0000
15.9200 18.0000 1.0000
15.9600 19.0000 1.0000
16.0000 21.0000 1.0000
16.0400 19.0000 1.0000
16.0800 33.0000 1.0000
16.1200 15.0000 1.0000
16.1600 22.0000 1.0000
16.2000 21.0000 1.0000
16.2400 17.0000 1.0000
16.2800 21.0000 1.0000
16.3200 29.0000 1.0000
16.3600 21.0000 1.0000
16.4000 15.0000 1.0000
16.4400 15.0000 1.0000
16.4800 17.0000 1.0000
16.5200 15.0000 1.0000
16.5600 21.0000 1.0000
16.6000 23.0000 1.0000
16.6400 24.0000 1.0000
16.6800 20.0000 1.0000
16.7200 24.0000 1.0000
16.7600 29.0000 1.0000
16.8000 23.0000 1.0000
16.8400 20.0000 1.0000
16.8800 27.0000 1.0000
16.9200 28.0000 1.0000
16.9600 22.0000 1.0000
17.0000 23.0000 1.0000
17.0400 23.0000 1.0000
17.0800 25.0000 1.0000
17.1200 20.0000 1.0000
17.1600 23.0000 1.0000
17.2000 21.0000 1.0000
17.2400 21.0000 1.0000
17.2800 20.0000 1.0000
17.3200 25.0000 1.0000
17.3600 25.0000 1.0000
17.4000 22.0000 1.0000
17.4400 20.0000 1.0000
17.4800 20.0000 1.0000
17.5200 27.0000 1.0000
17.5600 29.0000 1.0000
17.6000 30.0000 1.0000
17.6400 23.0000 1.0000
17.6800 38.0000 1.0000
17.7200 35.0000 1.0000
17.7600 19.0000 1.0000
17.8000 22.0000 1.0000
17.8400 23.0000 1.0000
17.8800 37.0000 1.0000
17.9200 17.0000 1.0000
17.9600 15.0000 1.0000
18.0000 27.0000 1.0000
18.0400 29.0000 1.0000
18.0800 18.0000 1.0000
18.1200 14.0000 1.0000
18.1600 16.0000 1.0000
18.2000 24.0000 1.0000
18.2400 18.0000 1.0000
18.2800 20.0000 1.0000
18.3200 18.0000 1.0000
18.3600 16.0000 1.0000
18.4000 20.0000 1.0000
18.4400 22.0000 1.0000
18.4800 17.0000 1.0000
18.5200 25.0000 1.0000
18.5600 21.0000 1.0000
18.6000 16.0000 1.0000
18.6400 24.0000 1.0000
18.6800 26.0000 1.0000
18.7200 30.0000 1.0000
18.7600 34.0000 1.0000
18.8000 54.0000 1.0000
18.8400 34.0000 1.0000
18.8800 36.0000 1.0000
18.9200 38.0000 1.0000
18.9600 26.0000 1.0000
19.0000 18.0000 1.0000
19.0400 23.0000 1.0000
19.0800 19.0000 1.0000
19.1200 22.0000 1.0000
19.1600 12.0000 1.0000
19.2000 12.0000 1.0000
19.2400 22.0000 1.0000
19.2800 11.0000 1.0000
19.3200 10.0000 1.0000
19.3600 25.0000 1.0000
19.4000 15.0000 1.0000
19.4400 12.0000 1.0000
19.4800 19.0000 1.0000
19.5200 16.0000 1.0000
19.5600 14.0000 1.0000
19.6000 13.0000 1.0000
19.6400 15.0000 1.0000
19.6800 20.0000 1.0000
19.7200 14.0000 1.0000
19.7600 17.0000 1.0000
19.8000 20.0000 1.0000
19.8400 10.0000 1.0000
19.8800 16.0000 1.0000
19.9200 16.0000 1.0000
19.9600 10.0000 1.0000
20.0000 14.0000 1.0000
20.0400 14.0000 1.0000
20.0800 19.0000 1.0000
20.1200 15.0000 1.0000
20.1600 12.0000 1.0000
20.2000 21.0000 1.0000
20.2400 13.0000 1.0000
20.2800 16.0000 1.0000
20.3200 10.0000 1.0000
20.3600 10.0000 1.0000
20.4000 14.0000 1.0000
20.4400 13.0000 1.0000
20.4800 9.0000 1.0000
20.5200 13.0000 1.0000
20.5600 17.0000 1.0000
20.6000 13.0000 1.0000
20.6400 9.0000 1.0000
20.6800 17.0000 1.0000
20.7200 8.0000 1.0000
20.7600 15.0000 1.0000
20.8000 11.0000 1.0000
20.8400 10.0000 1.0000
20.8800 22.0000 1.0000
20.9200 14.0000 1.0000
20.9600 10.0000 1.0000
21.0000 9.0000 1.0000
21.0400 9.0000 1.0000
21.0800 9.0000 1.0000
21.1200 16.0000 1.0000
21.1600 10.0000 1.0000
21.2000 12.0000 1.0000
21.2400 9.0000 1.0000
21.2800 10.0000 1.0000
21.3200 14.0000 1.0000
21.3600 9.0000 1.0000
21.4000 11.0000 1.0000
21.4400 13.0000 1.0000
21.4800 16.0000 1.0000
21.5200 14.0000 1.0000
21.5600 11.0000 1.0000
21.6000 11.0000 1.0000
21.6400 12.0000 1.0000
21.6800 13.0000 1.0000
21.7200 13.0000 1.0000
21.7600 13.0000 1.0000
21.8000 9.0000 1.0000
21.8400 8.0000 1.0000
21.8800 15.0000 1.0000
21.9200 12.0000 1.0000
21.9600 13.0000 1.0000
22.0000 9.0000 1.0000
22.0400 7.0000 1.0000
22.0800 11.0000 1.0000
22.1200 12.0000 1.0000
22.1600 15.0000 1.0000
22.2000 11.0000 1.0000
22.2400 7.0000 1.0000
22.2800 13.0000 1.0000
22.3200 13.0000 1.0000
22.3600 8.0000 1.0000
22.4000 15.0000 1.0000
22.4400 16.0000 1.0000
22.4800 10.0000 1.0000
22.5200 14.0000 1.0000
22.5600 21.0000 1.0000
22.6000 8.0000 1.0000
22.6400 9.0000 1.0000
22.6800 24.0000 1.0000
22.7200 21.0000 1.0000
22.7600 23.0000 1.0000
22.8000 28.0000 1.0000
22.8400 35.0000 1.0000
22.8800 22.0000 1.0000
22.9200 34.0000 1.0000
22.9600 16.0000 1.0000
23.0000 17.0000 1.0000
23.0400 20.0000 1.0000
23.0800 14.0000 1.0000
23.1200 10.0000 1.0000
23.1600 18.0000 1.0000
23.2000 12.0000 1.0000
23.2400 9.0000 1.0000
23.2800 11.0000 1.0000
23.3200 14.0000 1.0000
23.3600 10.0000 1.0000
23.4000 11.0000 1.0000
23.4400 16.0000 1.0000
23.4800 10.0000 1.0000
23.5200 11.0000 1.0000
23.5600 12.0000 1.0000
23.6000 5.0000 1.0000
23.6400 7.0000 1.0000
23.6800 10.0000 1.0000
23.7200 7.0000 1.0000
23.7600 12.0000 1.0000
23.8000 10.0000 1.0000
23.8400 12.0000 1.0000
23.8800 4.0000 1.0000
23.9200 10.0000 1.0000
23.9600 7.0000 1.0000
24.0000 5.0000 1.0000
24.0400 6.0000 1.0000
24.0800 13.0000 1.0000
24.1200 6.0000 1.0000
24.1600 8.0000 1.0000
24.2000 8.0000 1.0000
24.2400 7.0000 1.0000
24.2800 3.0000 1.0000
24.3200 9.0000 1.0000
24.3600 14.0000 1.0000
24.4000 7.0000 1.0000
24.4400 7.0000 1.0000
24.4800 6.0000 1.0000
24.5200 7.0000 1.0000
24.5600 12.0000 1.0000
24.6000 10.0000 1.0000
24.6400 7.0000 1.0000
24.6800 10.0000 1.0000
24.7200 10.0000 1.0000
24.7600 10.0000 1.0000
24.8000 9.0000 1.0000
24.8400 12.0000 1.0000
24.8800 7.0000 1.0000
24.9200 8.0000 1.0000
24.9600 10.0000 1.0000
25.0000 6.0000 1.0000
25.0400 4.0000 1.0000
25.0800 7.0000 1.0000
25.1200 8.0000 1.0000
25.1600 11.0000 1.0000
25.2000 11.0000 1.0000
25.2400 9.0000 1.0000
25.2800 13.0000 1.0000
25.3200 7.0000 1.0000
25.3600 4.0000 1.0000
25.4000 13.0000 1.0000
25.4400 10.0000 1.0000
25.4800 7.0000 1.0000
25.5200 6.0000 1.0000
25.5600 8.0000 1.0000
25.6000 13.0000 1.0000
25.6400 7.0000 1.0000
25.6800 10.0000 1.0000
25.7200 12.0000 1.0000
25.7600 7.0000 1.0000
25.8000 9.0000 1.0000
25.8400 9.0000 1.0000
25.8800 6.0000 1.0000
25.9200 13.0000 1.0000
25.9600 10.0000 1.0000
26.0000 7.0000 1.0000
26.0400 13.0000 1.0000
26.0800 11.0000 1.0000
26.1200 7.0000 1.0000
26.1600 7.0000 1.0000
26.2000 7.0000 1.0000
26.2400 5.0000 1.0000
26.2800 11.0000 1.0000
26.3200 8.0000 1.0000
26.3600 10.0000 1.0000
26.4000 6.0000 1.0000
26.4400 9.0000 1.0000
26.4800 8.0000 1.0000
26.5200 3.0000 1.0000
26.5600 6.0000 1.0000
26.6000 15.0000 1.0000
26.6400 10.0000 1.0000
26.6800 11.0000 1.0000
26.7200 8.0000 1.0000
26.7600 6.0000 1.0000
26.8000 13.0000 1.0000
26.8400 5.0000 1.0000
26.8800 9.0000 1.0000
26.9200 12.0000 1.0000
26.9600 10.0000 1.0000
27.0000 6.0000 1.0000
27.0400 8.0000 1.0000
27.0800 8.0000 1.0000
27.1200 8.0000 1.0000
27.1600 5.0000 1.0000
27.2000 4.0000 1.0000
27.2400 9.0000 1.0000
27.2800 12.0000 1.0000
27.3200 5.0000 1.0000
27.3600 9.0000 1.0000
27.4000 6.0000 1.0000
27.4400 8.0000 1.0000
27.4800 8.0000 1.0000
27.5200 9.0000 1.0000
27.5600 10.0000 1.0000
27.6000 11.0000 1.0000
27.6400 8.0000 1.0000
27.6800 3.0000 1.0000
27.7200 6.0000 1.0000
27.7600 8.0000 1.0000
27.8000 9.0000 1.0000
27.8400 7.0000 1.0000
27.8800 8.0000 1.0000
27.9200 10.0000 1.0000
27.9600 5.0000 1.0000
28.0000 9.0000 1.0000
28.0400 11.0000 1.0000
28.0800 9.0000 1.0000
28.1200 4.0000 1.0000
28.1600 12.0000 1.0000
28.2000 8.0000 1.0000
28.2400 5.0000 1.0000
28.2800 8.0000 1.0000
28.3200 10.0000 1.0000
28.3600 5.0000 1.0000
28.4000 3.0000 1.0000
28.4400 10.0000 1.0000
28.4800 9.0000 1.0000
28.5200 4.0000 1.0000
28.5600 8.0000 1.0000
28.6000 10.0000 1.0000
28.6400 9.0000 1.0000
28.6800 8.0000 1.0000
28.7200 7.0000 1.0000
28.7600 7.0000 1.0000
28.8000 11.0000 1.0000
28.8400 9.0000 1.0000
28.8800 9.0000 1.0000
28.9200 6.0000 1.0000
28.9600 7.0000 1.0000
29.0000 7.0000 1.0000
29.0400 11.0000 1.0000
29.0800 7.0000 1.0000
29.1200 6.0000 1.0000
29.1600 6.0000 1.0000
29.2000 14.0000 1.0000
29.2400 2.0000 1.0000
29.2800 4.0000 1.0000
29.3200 8.0000 1.0000
29.3600 5.0000 1.0000
29.4000 11.0000 1.0000
29.4400 6.0000 1.0000
29.4800 8.0000 1.0000
29.5200 12.0000 1.0000
29.5600 5.0000 1.0000
29.6000 6.0000 1.0000
29.6400 7.0000 1.0000
29.6800 8.0000 1.0000
29.7200 7.0000 1.0000
29.7600 8.0000 1.0000
29.8000 7.0000 1.0000
29.8400 10.0000 1.0000
29.8800 14.0000 1.0000
29.9200 13.0000 1.0000
29.9600 24.0000 1.0000
30.0000 33.0000 1.0000
30.0400 61.0000 1.0000
30.0800 80.0000 1.0000
30.1200 90.0000 1.0000
30.1600 126.0000 1.0000
30.2000 115.0000 1.0000
30.2400 96.0000 1.0000
30.2800 72.0000 1.0000
30.3200 55.0000 1.0000
30.3600 31.0000 1.0000
30.4000 14.0000 1.0000
30.4400 18.0000 1.0000
30.4800 22.0000 1.0000
30.5200 23.0000 1.0000
30.5600 29.0000 1.0000
30.6000 30.0000 1.0000
30.6400 47.0000 1.0000
30.6800 48.0000 1.0000
30.7200 42.0000 1.0000
30.7600 42.0000 1.0000
30.8000 26.0000 1.0000
30.8400 15.0000 1.0000
30.8800 8.0000 1.0000
30.9200 16.0000 1.0000
30.9600 12.0000 1.0000
31.0000 12.0000 1.0000
31.0400 16.0000 1.0000
31.0800 33.0000 1.0000
31.1200 32.0000 1.0000
31.1600 26.0000 1.0000
31.2000 30.0000 1.0000
31.2400 23.0000 1.0000
31.2800 20.0000 1.0000
31.3200 18.0000 1.0000
31.3600 9.0000 1.0000
31.4000 11.0000 1.0000
31.4400 15.0000 1.0000
31.4800 9.0000 1.0000
31.5200 12.0000 1.0000
31.5600 8.0000 1.0000
31.6000 12.0000 1.0000
31.6400 16.0000 1.0000
31.6800 16.0000 1.0000
31.7200 16.0000 1.0000
31.7600 28.0000 1.0000
31.8000 56.0000 1.0000
31.8400 61.0000 1.0000
31.8800 113.0000 1.0000
31.9200 131.0000 1.0000
31.9600 170.0000 1.0000
32.0000 218.0000 1.0000
32.0400 238.0000 1.0000
32.0800 216.0000 1.0000
32.1200 175.0000 1.0000
32.1600 132.0000 1.0000
32.2000 78.0000 1.0000
32.2400 38.0000 1.0000
32.2800 22.0000 1.0000
32.3200 16.0000 1.0000
32.3600 22.0000 1.0000
32.4000 13.0000 1.0000
32.4400 11.0000 1.0000
32.4800 9.0000 1.0000
32.5200 15.0000 1.0000
32.5600 7.0000 1.0000
32.6000 6.0000 1.0000
32.6400 9.0000 1.0000
32.6800 8.0000 1.0000
32.7200 6.0000 1.0000
32.7600 7.0000 1.0000
32.8000 6.0000 1.0000
32.8400 9.0000 1.0000
32.8800 8.0000 1.0000
32.9200 3.0000 1.0000
32.9600 7.0000 1.0000
33.0000 8.0000 1.0000
33.0400 8.0000 1.0000
33.0800 10.0000 1.0000
33.1200 8.0000 1.0000
33.1600 8.0000 1.0000
33.2000 10.0000 1.0000
33.2400 9.0000 1.0000
33.2800 6.0000 1.0000
33.3200 13.0000 1.0000
33.3600 4.0000 1.0000
33.4000 8.0000 1.0000
33.4400 8.0000 1.0000
33.4800 8.0000 1.0000
33.5200 7.0000 1.0000
33.5600 10.0000 1.0000
33.6000 19.0000 1.0000
33.6400 17.0000 1.0000
33.6800 23.0000 1.0000
33.7200 32.0000 1.0000
33.7600 48.0000 1.0000
33.8000 91.0000 1.0000
33.8400 138.0000 1.0000
33.8800 164.0000 1.0000
33.9200 233.0000 1.0000
33.9600 263.0000 1.0000
34.0000 266.0000 1.0000
34.0400 220.0000 1.0000
34.0800 167.0000 1.0000
34.1200 100.0000 1.0000
34.1600 69.0000 1.0000
34.2000 36.0000 1.0000
34.2400 21.0000 1.0000
34.2800 26.0000 1.0000
34.3200 20.0000 1.0000
34.3600 16.0000 1.0000
34.4000 14.0000 1.0000
34.4400 12.0000 1.0000
34.4800 14.0000 1.0000
34.5200 11.0000 1.0000
34.5600 9.0000 1.0000
34.6000 11.0000 1.0000
34.6400 10.0000 1.0000
34.6800 9.0000 1.0000
34.7200 10.0000 1.0000
34.7600 11.0000 1.0000
34.8000 9.0000 1.0000
34.8400 15.0000 1.0000
34.8800 18.0000 1.0000
34.9200 26.0000 1.0000
34.9600 21.0000 1.0000
35.0000 22.0000 1.0000
35.0400 43.0000 1.0000
35.0800 25.0000 1.0000
35.1200 19.0000 1.0000
35.1600 30.0000 1.0000
35.2000 28.0000 1.0000
35.2400 26.0000 1.0000
35.2800 16.0000 1.0000
35.3200 24.0000 1.0000
35.3600 25.0000 1.0000
35.4000 29.0000 1.0000
35.4400 28.0000 1.0000
35.4800 20.0000 1.0000
35.5200 22.0000 1.0000
35.5600 15.0000 1.0000
35.6000 15.0000 1.0000
35.6400 14.0000 1.0000
35.6800 10.0000 1.0000
35.7200 12.0000 1.0000
35.7600 6.0000 1.0000
35.8000 7.0000 1.0000
35.8400 10.0000 1.0000
35.8800 9.0000 1.0000
35.9200 8.0000 1.0000
35.9600 3.0000 1.0000
36.0000 9.0000 1.0000
36.0400 6.0000 1.0000
36.0800 9.0000 1.0000
36.1200 4.0000 1.0000
36.1600 6.0000 1.0000
36.2000 6.0000 1.0000
36.2400 4.0000 1.0000
36.2800 1.0000 1.0000
36.3200 6.0000 1.0000
36.3600 6.0000 1.0000
36.4000 9.0000 1.0000
36.4400 6.0000 1.0000
36.4800 8.0000 1.0000
36.5200 6.0000 1.0000
36.5600 9.0000 1.0000
36.6000 8.0000 1.0000
36.6400 19.0000 1.0000
36.6800 17.0000 1.0000
36.7200 19.0000 1.0000
36.7600 37.0000 1.0000
36.8000 76.0000 1.0000
36.8400 92.0000 1.0000
36.8800 109.0000 1.0000
36.9200 105.0000 1.0000
36.9600 123.0000 1.0000
37.0000 115.0000 1.0000
37.0400 92.0000 1.0000
37.0800 57.0000 1.0000
37.1200 38.0000 1.0000
37.1600 31.0000 1.0000
37.2000 17.0000 1.0000
37.2400 13.0000 1.0000
37.2800 8.0000 1.0000
37.3200 10.0000 1.0000
37.3600 5.0000 1.0000
37.4000 9.0000 1.0000
37.4400 9.0000 1.0000
37.4800 7.0000 1.0000
37.5200 10.0000 1.0000
37.5600 3.0000 1.0000
37.6000 6.0000 1.0000
37.6400 6.0000 1.0000
37.6800 3.0000 1.0000
37.7200 4.0000 1.0000
37.7600 2.0000 1.0000
37.8000 4.0000 1.0000
37.8400 3.0000 1.0000
37.8800 0.0000 1.0000
37.9200 6.0000 1.0000
37.9600 4.0000 1.0000
38.0000 3.0000 1.0000
38.0400 4.0000 1.0000
38.0800 8.0000 1.0000
38.1200 12.0000 1.0000
38.1600 5.0000 1.0000
38.2000 10.0000 1.0000
38.2400 7.0000 1.0000
38.2800 13.0000 1.0000
38.3200 12.0000 1.0000
38.3600 12.0000 1.0000
38.4000 7.0000 1.0000
38.4400 3.0000 1.0000
38.4800 11.0000 1.0000
38.5200 1.0000 1.0000
38.5600 6.0000 1.0000
38.6000 2.0000 1.0000
38.6400 11.0000 1.0000
38.6800 5.0000 1.0000
38.7200 7.0000 1.0000
38.7600 7.0000 1.0000
38.8000 6.0000 1.0000
38.8400 1.0000 1.0000
38.8800 10.0000 1.0000
38.9200 11.0000 1.0000
38.9600 15.0000 1.0000
39.0000 10.0000 1.0000
39.0400 13.0000 1.0000
39.0800 10.0000 1.0000
39.1200 6.0000 1.0000
39.1600 7.0000 1.0000
39.2000 7.0000 1.0000
39.2400 6.0000 1.0000
39.2800 3.0000 1.0000
39.3200 3.0000 1.0000
39.3600 5.0000 1.0000
39.4000 2.0000 1.0000
39.4400 6.0000 1.0000
39.4800 8.0000 1.0000
39.5200 2.0000 1.0000
39.5600 4.0000 1.0000
39.6000 6.0000 1.0000
39.6400 2.0000 1.0000
39.6800 7.0000 1.0000
39.7200 10.0000 1.0000
39.7600 9.0000 1.0000
39.8000 9.0000 1.0000
39.8400 11.0000 1.0000
39.8800 8.0000 1.0000
39.9200 16.0000 1.0000
39.9600 36.0000 1.0000
40.0000 35.0000 1.0000
40.0400 52.0000 1.0000
40.0800 58.0000 1.0000
40.1200 85.0000 1.0000
40.1600 99.0000 1.0000
40.2000 86.0000 1.0000
40.2400 70.0000 1.0000
40.2800 51.0000 1.0000
40.3200 42.0000 1.0000
40.3600 36.0000 1.0000
40.4000 18.0000 1.0000
40.4400 17.0000 1.0000
40.4800 14.0000 1.0000
40.5200 9.0000 1.0000
40.5600 5.0000 1.0000
40.6000 4.0000 1.0000
40.6400 5.0000 1.0000
40.6800 2.0000 1.0000
40.7200 7.0000 1.0000
40.7600 6.0000 1.0000
40.8000 4.0000 1.0000
40.8400 4.0000 1.0000
40.8800 2.0000 1.0000
40.9200 3.0000 1.0000
40.9600 7.0000 1.0000
41.0000 4.0000 1.0000
41.0400 4.0000 1.0000
41.0800 5.0000 1.0000
41.1200 4.0000 1.0000
41.1600 5.0000 1.0000
41.2000 6.0000 1.0000
41.2400 5.0000 1.0000
41.2800 3.0000 1.0000
41.3200 4.0000 1.0000
41.3600 3.0000 1.0000
41.4000 3.0000 1.0000
41.4400 6.0000 1.0000
41.4800 6.0000 1.0000
41.5200 5.0000 1.0000
41.5600 3.0000 1.0000
41.6000 3.0000 1.0000
41.6400 3.0000 1.0000
41.6800 8.0000 1.0000
41.7200 4.0000 1.0000
41.7600 5.0000 1.0000
41.8000 2.0000 1.0000
41.8400 6.0000 1.0000
41.8800 5.0000 1.0000
41.9200 6.0000 1.0000
41.9600 10.0000 1.0000
42.0000 6.0000 1.0000
42.0400 12.0000 1.0000
42.0800 18.0000 1.0000
42.1200 25.0000 1.0000
42.1600 48.0000 1.0000
42.2000 54.0000 1.0000
42.2400 58.0000 1.0000
42.2800 66.0000 1.0000
42.3200 63.0000 1.0000
42.3600 47.0000 1.0000
42.4000 32.0000 1.0000
42.4400 31.0000 1.0000
42.4800 20.0000 1.0000
42.5200 15.0000 1.0000
42.5600 9.0000 1.0000
42.6000 17.0000 1.0000
42.6400 9.0000 1.0000
42.6800 11.0000 1.0000
42.7200 12.0000 1.0000
42.7600 11.0000 1.0000
42.8000 6.0000 1.0000
42.8400 7.0000 1.0000
42.8800 4.0000 1.0000
42.9200 2.0000 1.0000
42.9600 5.0000 1.0000
43.0000 2.0000 1.0000
43.0400 6.0000 1.0000
43.0800 5.0000 1.0000
43.1200 3.0000 1.0000
43.1600 4.0000 1.0000
43.2000 2.0000 1.0000
43.2400 5.0000 1.0000
43.2800 5.0000 1.0000
43.3200 2.0000 1.0000
43.3600 3.0000 1.0000
43.4000 4.0000 1.0000
43.4400 7.0000 1.0000
43.4800 6.0000 1.0000
43.5200 5.0000 1.0000
43.5600 4.0000 1.0000
43.6000 7.0000 1.0000
43.6400 8.0000 1.0000
43.6800 6.0000 1.0000
43.7200 3.0000 1.0000
43.7600 3.0000 1.0000
43.8000 4.0000 1.0000
43.8400 8.0000 1.0000
43.8800 3.0000 1.0000
43.9200 3.0000 1.0000
43.9600 4.0000 1.0000
44.0000 3.0000 1.0000
44.0400 8.0000 1.0000
44.0800 3.0000 1.0000
44.1200 3.0000 1.0000
44.1600 4.0000 1.0000
44.2000 1.0000 1.0000
44.2400 5.0000 1.0000
44.2800 4.0000 1.0000
44.3200 3.0000 1.0000
44.3600 3.0000 1.0000
44.4000 3.0000 1.0000
44.4400 6.0000 1.0000
44.4800 4.0000 1.0000
44.5200 6.0000 1.0000
44.5600 7.0000 1.0000
44.6000 3.0000 1.0000
44.6400 5.0000 1.0000
44.6800 4.0000 1.0000
44.7200 3.0000 1.0000
44.7600 5.0000 1.0000
44.8000 7.0000 1.0000
44.8400 2.0000 1.0000
44.8800 4.0000 1.0000
44.9200 5.0000 1.0000
44.9600 4.0000 1.0000
45.0000 3.0000 1.0000
45.0400 4.0000 1.0000
45.0800 3.0000 1.0000
45.1200 3.0000 1.0000
45.1600 2.0000 1.0000
45.2000 2.0000 1.0000
45.2400 3.0000 1.0000
45.2800 1.0000 1.0000
45.3200 2.0000 1.0000
45.3600 3.0000 1.0000
45.4000 1.0000 1.0000
45.4400 4.0000 1.0000
45.4800 3.0000 1.0000
45.5200 5.0000 1.0000
45.5600 3.0000 1.0000
45.6000 3.0000 1.0000
45.6400 3.0000 1.0000
45.6800 2.0000 1.0000
45.7200 4.0000 1.0000
45.7600 4.0000 1.0000
45.8000 2.0000 1.0000
45.8400 2.0000 1.0000
45.8800 3.0000 1.0000
45.9200 3.0000 1.0000
45.9600 6.0000 1.0000
46.0000 1.0000 1.0000
46.0400 6.0000 1.0000
46.0800 5.0000 1.0000
46.1200 5.0000 1.0000
46.1600 5.0000 1.0000
46.2000 5.0000 1.0000
46.2400 7.0000 1.0000
46.2800 10.0000 1.0000
46.3200 12.0000 1.0000
46.3600 27.0000 1.0000
46.4000 19.0000 1.0000
46.4400 22.0000 1.0000
46.4800 22.0000 1.0000
46.5200 13.0000 1.0000
46.5600 11.0000 1.0000
46.6000 15.0000 1.0000
46.6400 6.0000 1.0000
46.6800 5.0000 1.0000
46.7200 8.0000 1.0000
46.7600 5.0000 1.0000
46.8000 5.0000 1.0000
46.8400 4.0000 1.0000
46.8800 5.0000 1.0000
46.9200 6.0000 1.0000
46.9600 5.0000 1.0000
47.0000 7.0000 1.0000
47.0400 4.0000 1.0000
47.0800 6.0000 1.0000
47.1200 8.0000 1.0000
47.1600 7.0000 1.0000
47.2000 8.0000 1.0000
47.2400 8.0000 1.0000
47.2800 8.0000 1.0000
47.3200 9.0000 1.0000
47.3600 6.0000 1.0000
47.4000 5.0000 1.0000
47.4400 6.0000 1.0000
47.4800 3.0000 1.0000
47.5200 8.0000 1.0000
47.5600 4.0000 1.0000
47.6000 4.0000 1.0000
47.6400 5.0000 1.0000
47.6800 6.0000 1.0000
47.7200 5.0000 1.0000
47.7600 6.0000 1.0000
47.8000 7.0000 1.0000
47.8400 2.0000 1.0000
47.8800 6.0000 1.0000
47.9200 4.0000 1.0000
47.9600 4.0000 1.0000
48.0000 5.0000 1.0000
48.0400 4.0000 1.0000
48.0800 4.0000 1.0000
48.1200 3.0000 1.0000
48.1600 5.0000 1.0000
48.2000 1.0000 1.0000
48.2400 5.0000 1.0000
48.2800 6.0000 1.0000
48.3200 3.0000 1.0000
48.3600 1.0000 1.0000
48.4000 5.0000 1.0000
48.4400 6.0000 1.0000
48.4800 6.0000 1.0000
48.5200 4.0000 1.0000
48.5600 3.0000 1.0000
48.6000 6.0000 1.0000
48.6400 5.0000 1.0000
48.6800 2.0000 1.0000
48.7200 1.0000 1.0000
48.7600 2.0000 1.0000
48.8000 3.0000 1.0000
48.8400 5.0000 1.0000
48.8800 8.0000 1.0000
48.9200 4.0000 1.0000
48.9600 3.0000 1.0000
49.0000 3.0000 1.0000
49.0400 5.0000 1.0000
49.0800 4.0000 1.0000
49.1200 2.0000 1.0000
49.1600 4.0000 1.0000
49.2000 5.0000 1.0000
49.2400 4.0000 1.0000
49.2800 3.0000 1.0000
49.3200 2.0000 1.0000
49.3600 4.0000 1.0000
49.4000 6.0000 1.0000
49.4400 6.0000 1.0000
49.4800 4.0000 1.0000
49.5200 6.0000 1.0000
49.5600 4.0000 1.0000
49.6000 5.0000 1.0000
49.6400 7.0000 1.0000
49.6800 8.0000 1.0000
49.7200 5.0000 1.0000
49.7600 11.0000 1.0000
49.8000 18.0000 1.0000
49.8400 12.0000 1.0000
49.8800 15.0000 1.0000
49.9200 20.0000 1.0000
49.9600 16.0000 1.0000
50.0000 16.0000 1.0000
*RAS_INT_END
*RAS_DATA_END